<mujoco model="pm01">
  <compiler angle="radian" meshdir="meshes/"/>

  <default>
    <joint armature="0.01" damping="5" frictionloss="1"/>
  </default>

  <visual>
    <headlight ambient=".4 .4 .4" diffuse=".8 .8 .8" specular="0.1 0.1 0.1"/>
    <rgba haze=".3 .3 .3 1"/>
  </visual>

  <asset>
    <texture type="2d" name="groundplane" builtin="checker" mark="edge" rgb1="0.2 0.3 0.4" rgb2="0.1 0.2 0.3" markrgb="0.8 0.8 0.8" width="300" height="300"/>
    <material name="groundplane" texture="groundplane" texrepeat="5 5" texuniform="true"/>

    <mesh name="link_base" content_type="model/stl" file="link_base.stl"/>
    <mesh name="link_hip_pitch_l" content_type="model/stl" file="link_hip_pitch_l.stl"/>
    <mesh name="link_hip_roll_l" content_type="model/stl" file="link_hip_roll_l.stl"/>
    <mesh name="link_hip_yaw_l" content_type="model/stl" file="link_hip_yaw_l.stl"/>
    <mesh name="link_knee_pitch_l" content_type="model/stl" file="link_knee_pitch_l.stl"/>
    <mesh name="link_ankle_pitch_l" content_type="model/stl" file="link_ankle_pitch_l.stl"/>
    <mesh name="link_ankle_roll_l" content_type="model/stl" file="link_ankle_roll_l.stl"/>
    <mesh name="link_hip_pitch_r" content_type="model/stl" file="link_hip_pitch_r.stl"/>
    <mesh name="link_hip_roll_r" content_type="model/stl" file="link_hip_roll_r.stl"/>
    <mesh name="link_hip_yaw_r" content_type="model/stl" file="link_hip_yaw_r.stl"/>
    <mesh name="link_knee_pitch_r" content_type="model/stl" file="link_knee_pitch_r.stl"/>
    <mesh name="link_ankle_pitch_r" content_type="model/stl" file="link_ankle_pitch_r.stl"/>
    <mesh name="link_ankle_roll_r" content_type="model/stl" file="link_ankle_roll_r.stl"/>
    <mesh name="link_torso_yaw" content_type="model/stl" file="link_torso_yaw.stl"/>
    <mesh name="link_shoulder_pitch_l" content_type="model/stl" file="link_shoulder_pitch_l.stl"/>
    <mesh name="link_shoulder_roll_l" content_type="model/stl" file="link_shoulder_roll_l.stl"/>
    <mesh name="link_shoulder_yaw_l" content_type="model/stl" file="link_shoulder_yaw_l.stl"/>
    <mesh name="link_elbow_pitch_l" content_type="model/stl" file="link_elbow_pitch_l.stl"/>
    <mesh name="link_elbow_yaw_l" content_type="model/stl" file="link_elbow_yaw_l.stl"/>
    <mesh name="link_shoulder_pitch_r" content_type="model/stl" file="link_shoulder_pitch_r.stl"/>
    <mesh name="link_shoulder_roll_r" content_type="model/stl" file="link_shoulder_roll_r.stl"/>
    <mesh name="link_shoulder_yaw_r" content_type="model/stl" file="link_shoulder_yaw_r.stl"/>
    <mesh name="link_elbow_pitch_r" content_type="model/stl" file="link_elbow_pitch_r.stl"/>
    <mesh name="link_elbow_yaw_r" content_type="model/stl" file="link_elbow_yaw_r.stl"/>
    <mesh name="link_head_yaw" content_type="model/stl" file="link_head_yaw.stl"/>
  </asset>

  <worldbody>
    <geom name="floor" pos="0 0 0" size="0 0 .05" type="plane" material="groundplane"/>

    <body name="link_base" pos="0 0 0.83">
      <freejoint name="root"/>
      <geom type="mesh" rgba="0.75294 0.75294 0.75294 1" mesh="link_base"/>
      <body name="link_hip_pitch_l" pos="0.01541 0.076141 -0.061208">
        <inertial pos="0.0101086 0.045246 -0.0119649" quat="0.644148 0.745776 0.169512 -0.0125773" mass="1.68628" diaginertia="0.00232449 0.00220186 0.00200187"/>
        <joint name="j00_hip_pitch_l" pos="0 0 0" axis="0 0.965926 -0.258819" range="-3.141 2.443" actuatorfrcrange="-164 164"/>
        <geom type="mesh" rgba="0.75294 0.75294 0.75294 1" mesh="link_hip_pitch_l"/>
        <body name="link_hip_roll_l" pos="0.048 0.049359 -0.013226">
          <inertial pos="-0.0186136 0.00234772 -0.0460198" quat="0.934255 0.0674459 -0.349492 -0.0217749" mass="0.632743" diaginertia="0.0016198 0.00145212 0.000966255"/>
          <joint name="j01_hip_roll_l" pos="0 0 0" axis="1 0 0" range="-0.436 2.094" actuatorfrcrange="-164 164"/>
          <geom type="mesh" rgba="0.75294 0.75294 0.75294 1" mesh="link_hip_roll_l"/>
          <body name="link_hip_yaw_l" pos="-0.03139 -0.0015951 -0.086016">
            <inertial pos="-0.00361155 0.00117239 -0.0931007" quat="0.979511 -0.00716725 -0.0443573 -0.196314" mass="1.858" diaginertia="0.0165126 0.01624 0.00332762"/>
            <joint name="j02_hip_yaw_l" pos="0 0 0" axis="0 0 1" range="-1.57 4.014" actuatorfrcrange="-52 52"/>
            <geom type="mesh" rgba="0.75294 0.75294 0.75294 1" mesh="link_hip_yaw_l"/>
            <body name="link_knee_pitch_l" pos="-0.02602 -2.8566e-05 -0.23655">
              <inertial pos="-0.00978702 0.00212191 -0.119309" quat="0.754298 -0.0350501 -0.0489895 0.653763" mass="4.29474" diaginertia="0.054833 0.053824 0.00490216"/>
              <joint name="j03_knee_pitch_l" pos="0 0 0" axis="0 1 0" range="-0.3491 2.3911" actuatorfrcrange="-164 164"/>
              <geom type="mesh" rgba="0.75294 0.75294 0.75294 1" mesh="link_knee_pitch_l"/>
              <body name="link_ankle_pitch_l" pos="-0.026756 0.00041994 -0.36305">
                <inertial pos="0.00126412 0 -0.00661445" quat="0.67654 -0.205654 -0.205654 0.67654" mass="0.115345" diaginertia="1.511e-05 1.42169e-05 1.17731e-05"/>
                <joint name="j04_ankle_pitch_l" pos="0 0 0" axis="0 1 0" range="-0.6807 0.7243" actuatorfrcrange="-52 52"/>
                <geom type="mesh" rgba="0.75294 0.75294 0.75294 1" mesh="link_ankle_pitch_l"/>
                <body name="link_ankle_roll_l" pos="0 0 -0.015">
                  <inertial pos="0.0145606 1.19e-06 -0.0221989" quat="-0.0050662 0.684809 0.00428214 0.728692" mass="0.717868" diaginertia="0.00293283 0.00276538 0.000568479"/>
                  <joint name="j05_ankle_roll_l" pos="0 0 0" axis="1 0 0" range="-0.2618 0.2618" actuatorfrcrange="-52 52"/>
                  <geom type="mesh" rgba="0.75294 0.75294 0.75294 1" mesh="link_ankle_roll_l"/>
                </body>
              </body>
            </body>
          </body>
        </body>
      </body>
      <body name="link_hip_pitch_r" pos="0.01541 -0.076141 -0.061208">
        <inertial pos="0.0102185 -0.0451673 -0.0122139" quat="0.774064 0.609636 0.00735361 -0.170631" mass="1.68024" diaginertia="0.00231922 0.00219067 0.00199347"/>
        <joint name="j06_hip_pitch_r" pos="0 0 0" axis="0 0.965926 0.258819" range="-3.141 2.443" actuatorfrcrange="-164 164"/>
        <geom type="mesh" rgba="0.75294 0.75294 0.75294 1" mesh="link_hip_pitch_r"/>
        <body name="link_hip_roll_r" pos="0.048 -0.04936 -0.013226">
          <inertial pos="-0.0184778 -0.00232999 -0.0457321" quat="0.935033 -0.0668104 -0.34737 0.0241446" mass="0.636736" diaginertia="0.00163098 0.00146337 0.000968649"/>
          <joint name="j07_hip_roll_r" pos="0 0 0" axis="1 0 0" range="-2.094 0.436" actuatorfrcrange="-164 164"/>
          <geom type="mesh" rgba="0.75294 0.75294 0.75294 1" mesh="link_hip_roll_r"/>
          <body name="link_hip_yaw_r" pos="-0.03139 0.0015966 -0.086016">
            <inertial pos="-0.00365713 -0.00305643 -0.096268" quat="0.98114 0.00638485 -0.0440517 0.188105" mass="1.83146" diaginertia="0.0162512 0.0159872 0.00326512"/>
            <joint name="j08_hip_yaw_r" pos="0 0 0" axis="0 0 1" range="-4.014 1.57" actuatorfrcrange="-52 52"/>
            <geom type="mesh" rgba="0.75294 0.75294 0.75294 1" mesh="link_hip_yaw_r"/>
            <body name="link_knee_pitch_r" pos="-0.02602 2.8566e-05 -0.23655">
              <inertial pos="-0.00985503 -0.00214867 -0.118986" quat="0.654986 -0.0492067 -0.0356218 0.753195" mass="4.29186" diaginertia="0.0544863 0.0534591 0.00492098"/>
              <joint name="j09_knee_pitch_r" pos="0 0 0" axis="0 1 0" range="-0.3491 2.3911" actuatorfrcrange="-164 164"/>
              <geom type="mesh" rgba="0.75294 0.75294 0.75294 1" mesh="link_knee_pitch_r"/>
              <body name="link_ankle_pitch_r" pos="-0.026756 -0.00041994 -0.36305">
                <inertial pos="0.00073183 0 -0.00669428" quat="0.667584 -0.233091 -0.233091 0.667584" mass="0.115345" diaginertia="1.511e-05 1.42164e-05 1.17736e-05"/>
                <joint name="j10_ankle_pitch_r" pos="0 0 0" axis="0 1 0" range="-0.6807 0.7243" actuatorfrcrange="-52 52"/>
                <geom type="mesh" rgba="0.75294 0.75294 0.75294 1" mesh="link_ankle_pitch_r"/>
                <body name="link_ankle_roll_r" pos="0 0 -0.015">
                  <inertial pos="0.0147067 1.452e-05 -0.0222658" quat="0.00494082 0.685204 -0.00483926 0.728318" mass="0.715592" diaginertia="0.00292483 0.00275765 0.000566261"/>
                  <joint name="j11_ankle_roll_r" pos="0 0 0" axis="1 0 0" range="-0.2618 0.2618" actuatorfrcrange="-52 52"/>
                  <geom type="mesh" rgba="0.75294 0.75294 0.75294 1" mesh="link_ankle_roll_r"/>
                </body>
              </body>
            </body>
          </body>
        </body>
      </body>
      <body name="link_torso_yaw" pos="0.01216 0 0.0809">
        <inertial pos="-0.0114072 -0.00348592 0.162838" quat="0.995948 -0.0278316 0.0854008 -0.00437854" mass="9.01442" diaginertia="0.0858373 0.0656652 0.056708"/>
        <joint name="j12_waist_yaw" pos="0 0 0" axis="0 0 1" range="-4.014 1.57" actuatorfrcrange="-52 52"/>
        <geom type="mesh" rgba="0.75294 0.75294 0.75294 1" mesh="link_torso_yaw"/>
        <body name="link_shoulder_pitch_l" pos="-0.027105 0.12916 0.21549">
          <inertial pos="-0.0068739 0.0562468 -0.0156415" quat="0.526158 0.83672 -0.143374 0.0500143" mass="0.932155" diaginertia="0.00125198 0.00108471 0.000622336"/>
          <joint name="j13_shoulder_pitch_l" pos="0 0 0" axis="0 0.998027 0.0627908" range="-2.9671 2.7925" actuatorfrcrange="-52 52"/>
          <geom type="mesh" rgba="0.75294 0.75294 0.75294 1" mesh="link_shoulder_pitch_l"/>
          <body name="link_shoulder_roll_l" pos="-0.0371 0.066941 -0.020838">
            <inertial pos="0.037412 0.00677175 -0.0267801" quat="0.694988 -0.115505 0.0954646 0.703233" mass="0.510813" diaginertia="0.0013316 0.000992823 0.000901346"/>
            <joint name="j14_shoulder_roll_l" pos="0 0 0" axis="1 0 0" range="-0.6108 2.3562" actuatorfrcrange="-52 52"/>
            <geom type="mesh" rgba="0.75294 0.75294 0.75294 1" mesh="link_shoulder_roll_l"/>
            <body name="link_shoulder_yaw_l" pos="0.0371 0.017645 -0.070132">
              <inertial pos="-0.00084545 0.00219391 -0.045665" quat="0.999922 -0.00834297 -0.00593057 0.00715565" mass="0.909138" diaginertia="0.00162177 0.00150888 0.000787082"/>
              <joint name="j15_shoulder_yaw_l" pos="0 0 0" axis="0 -0.0628027 0.998026" range="-2.618 2.618" actuatorfrcrange="-52 52"/>
              <geom type="mesh" rgba="0.75294 0.75294 0.75294 1" mesh="link_shoulder_yaw_l"/>
              <body name="link_elbow_pitch_l" pos="0 0.0065994 -0.10487">
                <inertial pos="0.00298237 0.00186711 -0.0651846" quat="0.850602 -0.0227837 0.0480929 0.52311" mass="1.38061" diaginertia="0.00600679 0.00586987 0.000776466"/>
                <joint name="j16_elbow_pitch_l" pos="0 0 0" axis="0.00272431 0.998022 0.0628031" range="-2.1948 0.7374" actuatorfrcrange="-52 52"/>
                <geom type="mesh" rgba="0.75294 0.75294 0.75294 1" mesh="link_elbow_pitch_l"/>
                <body name="link_elbow_yaw_l" pos="0.013817 0.0097723 -0.1547">
                  <inertial pos="0.020164 0.00026082 -0.0899072" quat="0.993628 -0.0140101 -0.111518 -0.00840885" mass="0.466519" diaginertia="0.00174311 0.00173218 0.000322375"/>
                  <joint name="j17_elbow_yaw_l" pos="0 0 0" axis="-0.214789 -0.0619207 0.974696" range="-2.618 2.618" actuatorfrcrange="-52 52"/>
                  <geom type="mesh" rgba="0.75294 0.75294 0.75294 1" mesh="link_elbow_yaw_l"/>
                </body>
              </body>
            </body>
          </body>
        </body>
        <body name="link_shoulder_pitch_r" pos="-0.027105 -0.12916 0.21549">
          <inertial pos="-0.00682535 -0.0562853 -0.0156716" quat="0.835241 0.527808 -0.0515869 0.145363" mass="0.929141" diaginertia="0.0012533 0.00108394 0.000621161"/>
          <joint name="j18_shoulder_pitch_r" pos="0 0 0" axis="0 0.998027 -0.0627908" range="-2.9671 2.7925" actuatorfrcrange="-52 52"/>
          <geom type="mesh" rgba="0.75294 0.75294 0.75294 1" mesh="link_shoulder_pitch_r"/>
          <body name="link_shoulder_roll_r" pos="-0.0371 -0.066941 -0.020838">
            <inertial pos="0.0374584 -0.00675724 -0.0267111" quat="0.702814 0.0963237 -0.114817 0.695408" mass="0.509678" diaginertia="0.00132926 0.000991635 0.000900119"/>
            <joint name="j19_shoulder_roll_r" pos="0 0 0" axis="1 0 0" range="-2.3562 0.6108" actuatorfrcrange="-52 52"/>
            <geom type="mesh" rgba="0.75294 0.75294 0.75294 1" mesh="link_shoulder_roll_r"/>
            <body name="link_shoulder_yaw_r" pos="0.0371 -0.017644 -0.070132">
              <inertial pos="-0.00081742 -0.00217677 -0.0456691" quat="0.999939 0.00845362 -0.00629935 -0.00342591" mass="0.908517" diaginertia="0.00162116 0.00150819 0.000786341"/>
              <joint name="j20_shoulder_yaw_r" pos="0 0 0" axis="0 0.0627908 0.998027" range="-2.618 2.618" actuatorfrcrange="-52 52"/>
              <geom type="mesh" rgba="0.75294 0.75294 0.75294 1" mesh="link_shoulder_yaw_r"/>
              <body name="link_elbow_pitch_r" pos="0 -0.006598 -0.10487">
                <inertial pos="0.00302244 -0.00191447 -0.0652115" quat="0.525604 0.0481342 -0.0227734 0.849061" mass="1.38163" diaginertia="0.00600585 0.00586931 0.000776263"/>
                <joint name="j21_elbow_pitch_r" pos="0 0 0" axis="0.00272431 0.998023 -0.0627902" range="-2.1948 0.7374" actuatorfrcrange="-52 52"/>
                <geom type="mesh" rgba="0.75294 0.75294 0.75294 1" mesh="link_elbow_pitch_r"/>
                <body name="link_elbow_yaw_r" pos="0.013817 -0.0097704 -0.1547">
                  <inertial pos="0.0202166 -0.00026434 -0.089931" quat="0.993715 0.0158198 -0.110576 -0.00726878" mass="0.466481" diaginertia="0.00173944 0.00172851 0.00032237"/>
                  <joint name="j22_elbow_yaw_r" pos="0 0 0" axis="-0.214789 0.0619088 0.974696" range="-2.618 2.618" actuatorfrcrange="-52 52"/>
                  <geom type="mesh" rgba="0.75294 0.75294 0.75294 1" mesh="link_elbow_yaw_r"/>
                </body>
              </body>
            </body>
          </body>
        </body>
        <body name="link_head_yaw" pos="-0.017638 0 0.2961">
          <inertial pos="0.00358213 0.00030109 0.0882263" quat="0.700279 0.122834 0.123579 0.692278" mass="0.8451" diaginertia="0.00500549 0.00445883 0.00296172"/>
          <joint name="j23_head_yaw" pos="0 0 0" axis="0 0 1" range="-0.6109 0.6109" actuatorfrcrange="-52 52"/>
          <geom type="mesh" rgba="0.75294 0.75294 0.75294 1" mesh="link_head_yaw"/>
        </body>
      </body>
    </body>
  </worldbody>
</mujoco>
